Workbook

Sheet Inputs
A1: Stormwater detention | calculation workbook
A2: Green cells contain independent formulas. Scenario tables are saved Python results; changing this workbook does not rerun the grid.
A3: Parking area | B3: 4000 | C3: m²
A4: Basin footprint | B4: 200 | C4: m²
A5: Curve number | B5: 98 | C5: assumed
A6: Initial abstraction / S | B6: 0.2 | C6: ratio
A7: Lag | B7: 10 | C7: min
A8: Discharge coefficient | B8: 0.62 | C8: assumed
A9: Gravity | B9: 9.80665 | C9: m/s²
A10: Selected depth | B10: 0.75 | C10: m; example if infeasible
A11: Outlet side | B11: 0.1 | C11: m
A12: Final simulation step | B12: 1.875 | C12: s
A13: Storage capacity | B13: =B4*B10 -> 150 | C13: m³
A14: Design rainfall | B14: 50 | C14: mm
A15: Absolute check tolerance | B15: 1e-08 | C15: m³
A18: Site area is 4,200 m² in every default case. Direct footprint rainfall joins the baseline discharge or basin storage. Zero basin infiltration; detention changes timing, not total event runoff.

Sheet Runoff checks
A1: Independent CN volume calculation
A2: These cells calculate retention, initial abstraction, excess depth, and runoff volume directly from Excel formulas. Column H is only the comparison reference.
A4: Rain (mm) | B4: S (mm) | C4: Ia (mm) | D4: Excess (mm) | E4: Parking (m³) | F4: Footprint (m³) | G4: Total (m³) | H4: Python total (m³) | I4: Difference (m³) | J4: Pass
A5: 25 | B5: =25400/Inputs!B5-254 -> 5.1836735 | C5: =Inputs!B6*B5 -> 1.0367347 | D5: =IF(A5<=C5,0,(A5-C5)^2/(A5-C5+B5)) -> 19.701489 | E5: =D5*Inputs!B3/1000 -> 78.805955 | F5: =A5*Inputs!B4/1000 -> 5 | G5: =E5+F5 -> 83.805955 | H5: 83.805955 | I5: =G5-H5 -> 0 | J5: =ABS(I5)<=Inputs!B15 -> TRUE
A6: 50 | B6: =25400/Inputs!B5-254 -> 5.1836735 | C6: =Inputs!B6*B6 -> 1.0367347 | D6: =IF(A6<=C6,0,(A6-C6)^2/(A6-C6+B6)) -> 44.275843 | E6: =D6*Inputs!B3/1000 -> 177.10337 | F6: =A6*Inputs!B4/1000 -> 10 | G6: =E6+F6 -> 187.10337 | H6: 187.10337 | I6: =G6-H6 -> -2.8421709e-14 | J6: =ABS(I6)<=Inputs!B15 -> TRUE
A7: 100 | B7: =25400/Inputs!B5-254 -> 5.1836735 | C7: =Inputs!B6*B7 -> 1.0367347 | D7: =IF(A7<=C7,0,(A7-C7)^2/(A7-C7+B7)) -> 94.037597 | E7: =D7*Inputs!B3/1000 -> 376.15039 | F7: =A7*Inputs!B4/1000 -> 20 | G7: =E7+F7 -> 396.15039 | H7: 396.15039 | I7: =G7-H7 -> 0 | J7: =ABS(I7)<=Inputs!B15 -> TRUE
A11: Try CN 95 or 100 on Inputs. Columns B–G recompute; the Python reference stays fixed until run_project.py is rerun. Initial abstraction is applied once to cumulative rainfall. Depth × area / 1,000 converts mm to m³.

Sheet Storage check
A1: Independent continuity | blocked outlet
A2: A separate exact fixture: 1 m³/s for eight 5-second steps into a 20 m³ tank, with no controlled outlet. After filling, every extra m³ becomes overflow.
A3: Capacity (m³) | B3: 20 | D3: Step (s) | E3: 5
A5: Step | B5: Time end (s) | C5: Inflow (m³/s) | D5: Start S (m³) | E5: Available (m³) | F5: End S (m³) | G5: Overflow (m³) | H5: Cumulative overflow | I5: Step residual (m³)
A6: 1 | B6: =A6*$E$3 -> 5 | C6: 1 | D6: 0 | E6: =D6+C6*$E$3 -> 5 | F6: =MIN($B$3,E6) -> 5 | G6: =MAX(E6-$B$3,0) -> 0 | H6: =G6 -> 0 | I6: =D6+C6*$E$3-F6-G6 -> 0
A7: 2 | B7: =A7*$E$3 -> 10 | C7: 1 | D7: =F6 -> 5 | E7: =D7+C7*$E$3 -> 10 | F7: =MIN($B$3,E7) -> 10 | G7: =MAX(E7-$B$3,0) -> 0 | H7: =H6+G7 -> 0 | I7: =D7+C7*$E$3-F7-G7 -> 0
A8: 3 | B8: =A8*$E$3 -> 15 | C8: 1 | D8: =F7 -> 10 | E8: =D8+C8*$E$3 -> 15 | F8: =MIN($B$3,E8) -> 15 | G8: =MAX(E8-$B$3,0) -> 0 | H8: =H7+G8 -> 0 | I8: =D8+C8*$E$3-F8-G8 -> 0
A9: 4 | B9: =A9*$E$3 -> 20 | C9: 1 | D9: =F8 -> 15 | E9: =D9+C9*$E$3 -> 20 | F9: =MIN($B$3,E9) -> 20 | G9: =MAX(E9-$B$3,0) -> 0 | H9: =H8+G9 -> 0 | I9: =D9+C9*$E$3-F9-G9 -> 0
A10: 5 | B10: =A10*$E$3 -> 25 | C10: 1 | D10: =F9 -> 20 | E10: =D10+C10*$E$3 -> 25 | F10: =MIN($B$3,E10) -> 20 | G10: =MAX(E10-$B$3,0) -> 5 | H10: =H9+G10 -> 5 | I10: =D10+C10*$E$3-F10-G10 -> 0
A11: 6 | B11: =A11*$E$3 -> 30 | C11: 1 | D11: =F10 -> 20 | E11: =D11+C11*$E$3 -> 25 | F11: =MIN($B$3,E11) -> 20 | G11: =MAX(E11-$B$3,0) -> 5 | H11: =H10+G11 -> 10 | I11: =D11+C11*$E$3-F11-G11 -> 0
A12: 7 | B12: =A12*$E$3 -> 35 | C12: 1 | D12: =F11 -> 20 | E12: =D12+C12*$E$3 -> 25 | F12: =MIN($B$3,E12) -> 20 | G12: =MAX(E12-$B$3,0) -> 5 | H12: =H11+G12 -> 15 | I12: =D12+C12*$E$3-F12-G12 -> 0
A13: 8 | B13: =A13*$E$3 -> 40 | C13: 1 | D13: =F12 -> 20 | E13: =D13+C13*$E$3 -> 25 | F13: =MIN($B$3,E13) -> 20 | G13: =MAX(E13-$B$3,0) -> 5 | H13: =H12+G13 -> 20 | I13: =D13+C13*$E$3-F13-G13 -> 0
A16: Total input (m³) | B16: =8*$E$3 -> 40
A17: Storage + overflow (m³) | B17: =F13+H13 -> 40
A18: Water balance pass | B18: =ABS(B16-B17)<=Inputs!B15 -> TRUE

Sheet Implicit step
A1: Independent Excel bisection | one storage step
A2: 45 formula iterations solve Snew + dt × Q(Snew/A) = Sold + Vin. This reproduces a controlled-outlet step without calling Python's root finder.
A4: Area (m²) | B4: 200 | I4: Formula final S (m³) | J4: =D59 -> 41.285453
A5: Capacity (m³) | B5: 120 | I5: Python comparison S | J5: 41.285453
A6: Old storage (m³) | B6: 40 | I6: Difference (m³) | J6: =J4-J5 -> -1.0871304e-12
A7: Inflow volume (m³) | B7: 1.5 | I7: Independent check pass | J7: =ABS(J6)<=Inputs!B15 -> TRUE
A8: Step (s) | B8: 30 | I8: Equation residual (m³) | J8: =G59 -> -1.0871304e-12
A9: Opening side (m) | B9: 0.08
A10: Cd | B10: 0.62
A11: Gravity (m/s²) | B11: 9.80665
A14: Iteration | B14: Lower S | C14: Upper S | D14: Midpoint S | E14: Depth (m) | F14: Outlet (m³/s) | G14: Equation residual (m³)
A15: 1 | B15: 0 | C15: =MIN($B$5,$B$6+$B$7) -> 41.5 | D15: =(B15+C15)/2 -> 20.75 | E15: =D15/$B$4 -> 0.10375 | F15: =(2/3)*$B$10*$B$9*SQRT(2*$B$11)*(E15^1.5-MAX(E15-$B$9,0)^1.5) -> 0.0043578236 | G15: =D15+$B$8*F15-($B$6+$B$7) -> -20.619265
A16: 2 | B16: =IF(G15>0,B15,D15) -> 20.75 | C16: =IF(G15>0,D15,C15) -> 41.5 | D16: =(B16+C16)/2 -> 31.125 | E16: =D16/$B$4 -> 0.155625 | F16: =(2/3)*$B$10*$B$9*SQRT(2*$B$11)*(E16^1.5-MAX(E16-$B$9,0)^1.5) -> 0.0059449831 | G16: =D16+$B$8*F16-($B$6+$B$7) -> -10.196651
A17: 3 | B17: =IF(G16>0,B16,D16) -> 31.125 | C17: =IF(G16>0,D16,C16) -> 41.5 | D17: =(B17+C17)/2 -> 36.3125 | E17: =D17/$B$4 -> 0.1815625 | F17: =(2/3)*$B$10*$B$9*SQRT(2*$B$11)*(E17^1.5-MAX(E17-$B$9,0)^1.5) -> 0.0065894863 | G17: =D17+$B$8*F17-($B$6+$B$7) -> -4.9898154
A18: 4 | B18: =IF(G17>0,B17,D17) -> 36.3125 | C18: =IF(G17>0,D17,C17) -> 41.5 | D18: =(B18+C18)/2 -> 38.90625 | E18: =D18/$B$4 -> 0.19453125 | F18: =(2/3)*$B$10*$B$9*SQRT(2*$B$11)*(E18^1.5-MAX(E18-$B$9,0)^1.5) -> 0.0068885109 | G18: =D18+$B$8*F18-($B$6+$B$7) -> -2.3870947
A19: 5 | B19: =IF(G18>0,B18,D18) -> 38.90625 | C19: =IF(G18>0,D18,C18) -> 41.5 | D19: =(B19+C19)/2 -> 40.203125 | E19: =D19/$B$4 -> 0.20101563 | F19: =(2/3)*$B$10*$B$9*SQRT(2*$B$11)*(E19^1.5-MAX(E19-$B$9,0)^1.5) -> 0.0070331447 | G19: =D19+$B$8*F19-($B$6+$B$7) -> -1.0858807
A20: 6 | B20: =IF(G19>0,B19,D19) -> 40.203125 | C20: =IF(G19>0,D19,C19) -> 41.5 | D20: =(B20+C20)/2 -> 40.851562 | E20: =D20/$B$4 -> 0.20425781 | F20: =(2/3)*$B$10*$B$9*SQRT(2*$B$11)*(E20^1.5-MAX(E20-$B$9,0)^1.5) -> 0.0071043337 | G20: =D20+$B$8*F20-($B$6+$B$7) -> -0.43530749
A21: 7 | B21: =IF(G20>0,B20,D20) -> 40.851562 | C21: =IF(G20>0,D20,C20) -> 41.5 | D21: =(B21+C21)/2 -> 41.175781 | E21: =D21/$B$4 -> 0.20587891 | F21: =(2/3)*$B$10*$B$9*SQRT(2*$B$11)*(E21^1.5-MAX(E21-$B$9,0)^1.5) -> 0.0071396565 | G21: =D21+$B$8*F21-($B$6+$B$7) -> -0.11002906
A22: 8 | B22: =IF(G21>0,B21,D21) -> 41.175781 | C22: =IF(G21>0,D21,C21) -> 41.5 | D22: =(B22+C22)/2 -> 41.337891 | E22: =D22/$B$4 -> 0.20668945 | F22: =(2/3)*$B$10*$B$9*SQRT(2*$B$11)*(E22^1.5-MAX(E22-$B$9,0)^1.5) -> 0.0071572512 | G22: =D22+$B$8*F22-($B$6+$B$7) -> 0.05260816
A23: 9 | B23: =IF(G22>0,B22,D22) -> 41.175781 | C23: =IF(G22>0,D22,C22) -> 41.337891 | D23: =(B23+C23)/2 -> 41.256836 | E23: =D23/$B$4 -> 0.20628418 | F23: =(2/3)*$B$10*$B$9*SQRT(2*$B$11)*(E23^1.5-MAX(E23-$B$9,0)^1.5) -> 0.0071484593 | G23: =D23+$B$8*F23-($B$6+$B$7) -> -0.028710283
A24: 10 | B24: =IF(G23>0,B23,D23) -> 41.256836 | C24: =IF(G23>0,D23,C23) -> 41.337891 | D24: =(B24+C24)/2 -> 41.297363 | E24: =D24/$B$4 -> 0.20648682 | F24: =(2/3)*$B$10*$B$9*SQRT(2*$B$11)*(E24^1.5-MAX(E24-$B$9,0)^1.5) -> 0.0071528566 | G24: =D24+$B$8*F24-($B$6+$B$7) -> 0.01194898
A25: 11 | B25: =IF(G24>0,B24,D24) -> 41.256836 | C25: =IF(G24>0,D24,C24) -> 41.297363 | D25: =(B25+C25)/2 -> 41.2771 | E25: =D25/$B$4 -> 0.2063855 | F25: =(2/3)*$B$10*$B$9*SQRT(2*$B$11)*(E25^1.5-MAX(E25-$B$9,0)^1.5) -> 0.0071506583 | G25: =D25+$B$8*F25-($B$6+$B$7) -> -0.008380641
A26: 12 | B26: =IF(G25>0,B25,D25) -> 41.2771 | C26: =IF(G25>0,D25,C25) -> 41.297363 | D26: =(B26+C26)/2 -> 41.287231 | E26: =D26/$B$4 -> 0.20643616 | F26: =(2/3)*$B$10*$B$9*SQRT(2*$B$11)*(E26^1.5-MAX(E26-$B$9,0)^1.5) -> 0.0071517576 | G26: =D26+$B$8*F26-($B$6+$B$7) -> 0.001784172
A27: 13 | B27: =IF(G26>0,B26,D26) -> 41.2771 | C27: =IF(G26>0,D26,C26) -> 41.287231 | D27: =(B27+C27)/2 -> 41.282166 | E27: =D27/$B$4 -> 0.20641083 | F27: =(2/3)*$B$10*$B$9*SQRT(2*$B$11)*(E27^1.5-MAX(E27-$B$9,0)^1.5) -> 0.007151208 | G27: =D27+$B$8*F27-($B$6+$B$7) -> -0.0032982338
... A59: 45 | B59: =IF(G58>0,B58,D58) -> 41.285453 | C59: =IF(G58>0,D58,C58) -> 41.285453 | D59: =(B59+C59)/2 -> 41.285453 | E59: =D59/$B$4 -> 0.20642727 | F59: =(2/3)*$B$10*$B$9*SQRT(2*$B$11)*(E59^1.5-MAX(E59-$B$9,0)^1.5) -> 0.0071515646 | G59: =D59+$B$8*F59-($B$6+$B$7) -> -1.0871304e-12

Sheet Scenarios
A1: All candidate-event results
A2: Imported numerical results at the verified final resolution; flow is m³/s and downstream discharge includes overflow.
A4: event_id | B4: rainfall_mm | C4: shape | D4: dt_s | E4: horizon_h | F4: curve_number | G4: lag_min | H4: discharge_coefficient | I4: rainfall_total_mm | J4: parking_runoff_m3 | K4: direct_rain_m3 | L4: total_inflow_m3 | M4: runoff_generation_error_m3 | N4: transform_error_m3 | O4: inflow_tail_end_h | P4: baseline_peak_m3_s | Q4: baseline_time_to_peak_min | R4: design_id | S4: storage_depth_m | T4: capacity_m3 | U4: outlet_side_mm | V4: peak_downstream_m3_s | W4: peak_reduction_pct | X4: time_to_peak_min | Y4: maximum_storage_m3 | Z4: maximum_depth_m | AA4: overflow_m3 | AB4: overflow_onset_min | AC4: controlled_discharge_m3 | AD4: total_discharge_m3 | AE4: residual_storage_m3 | AF4: drawdown_h_after_rain | AG4: routing_balance_error_m3 | AH4: routing_balance_relative_error | AI4: peak_pass | AJ4: overflow_pass | AK4: drawdown_pass | AL4: simulation_runtime_s | AM4: all_pass
A5: 25mm_uniform | B5: 25 | C5: uniform | D5: 1.875 | E5: 60 | F5: 98 | G5: 10 | H5: 0.62 | I5: 25 | J5: 78.805955 | K5: 5 | L5: 83.805955 | M5: -1.4210855e-14 | N5: 1.4210855e-14 | O5: 1.834375 | P5: 0.027765527 | Q5: 59.984375 | R5: h0.150_o40 | S5: 0.15 | T5: 30 | U5: 40 | V5: 0.027765527 | W5: -2.3092639e-12 | X5: 59.984375 | Y5: 30 | Z5: 0.15 | AA5: 47.694353 | AB5: 40.28125 | AC5: 35.985701 | AD5: 83.680054 | AE5: 0.12590053 | AF5: 37.699157 | AG5: -5.1908478e-13 | AH5: 6.1938889e-15 | AI5: FALSE | AJ5: FALSE | AK5: FALSE | AL5: 1.0452363 | AM5: FALSE
A6: 25mm_uniform | B6: 25 | C6: uniform | D6: 1.875 | E6: 30 | F6: 98 | G6: 10 | H6: 0.62 | I6: 25 | J6: 78.805955 | K6: 5 | L6: 83.805955 | M6: -1.4210855e-14 | N6: 1.4210855e-14 | O6: 1.834375 | P6: 0.027765527 | Q6: 59.984375 | R6: h0.150_o60 | S6: 0.15 | T6: 30 | U6: 60 | V6: 0.027765527 | W6: -2.3092639e-12 | X6: 59.984375 | Y6: 30 | Z6: 0.15 | AA6: 41.845344 | AB6: 41.1875 | AC6: 41.743706 | AD6: 83.58905 | AE6: 0.21690471 | AF6: 24.401299 | AG6: 1.0904333e-12 | AH6: 1.3011406e-14 | AI6: FALSE | AJ6: FALSE | AK6: FALSE | AL6: 0.352349 | AM6: FALSE
A7: 25mm_uniform | B7: 25 | C7: uniform | D7: 1.875 | E7: 30 | F7: 98 | G7: 10 | H7: 0.62 | I7: 25 | J7: 78.805955 | K7: 5 | L7: 83.805955 | M7: -1.4210855e-14 | N7: 1.4210855e-14 | O7: 1.834375 | P7: 0.027765527 | Q7: 59.984375 | R7: h0.150_o80 | S7: 0.15 | T7: 30 | U7: 80 | V7: 0.027765527 | W7: -2.3092639e-12 | X7: 59.984375 | Y7: 30 | Z7: 0.15 | AA7: 35.11506 | AB7: 42.375 | AC7: 48.566706 | AD7: 83.681766 | AE7: 0.12418842 | AF7: 18.141662 | AG7: 3.8942821e-11 | AH7: 4.6467845e-13 | AI7: FALSE | AJ7: FALSE | AK7: TRUE | AL7: 0.35005429 | AM7: FALSE
A8: 25mm_uniform | B8: 25 | C8: uniform | D8: 1.875 | E8: 30 | F8: 98 | G8: 10 | H8: 0.62 | I8: 25 | J8: 78.805955 | K8: 5 | L8: 83.805955 | M8: -1.4210855e-14 | N8: 1.4210855e-14 | O8: 1.834375 | P8: 0.027765527 | Q8: 59.984375 | R8: h0.150_o100 | S8: 0.15 | T8: 30 | U8: 100 | V8: 0.027765527 | W8: -2.3092639e-12 | X8: 59.984375 | Y8: 30 | Z8: 0.15 | AA8: 28.062868 | AB8: 43.8125 | AC8: 55.662222 | AD8: 83.725089 | AE8: 0.080865584 | AF8: 14.485263 | AG8: 1.7799161e-10 | AH8: 2.1238539e-12 | AI8: FALSE | AJ8: FALSE | AK8: TRUE | AL8: 0.34875875 | AM8: FALSE
A9: 25mm_uniform | B9: 25 | C9: uniform | D9: 1.875 | E9: 60 | F9: 98 | G9: 10 | H9: 0.62 | I9: 25 | J9: 78.805955 | K9: 5 | L9: 83.805955 | M9: -1.4210855e-14 | N9: 1.4210855e-14 | O9: 1.834375 | P9: 0.027765527 | Q9: 59.984375 | R9: h0.300_o40 | S9: 0.3 | T9: 60 | U9: 40 | V9: 0.026398686 | W9: 4.9227966 | X9: 60.828125 | Y9: 60 | Z9: 0.3 | AA9: 16.189941 | AB9: 60.34375 | AC9: 67.47047 | AD9: 83.660411 | AE9: 0.14554337 | AF9: 30.452305 | AG9: -3.2676639e-12 | AH9: 3.8990832e-14 | AI9: FALSE | AJ9: FALSE | AK9: FALSE | AL9: 1.0517302 | AM9: FALSE
A10: 25mm_uniform | B10: 25 | C10: uniform | D10: 1.875 | E10: 30 | F10: 98 | G10: 10 | H10: 0.62 | I10: 25 | J10: 78.805955 | K10: 5 | L10: 83.805955 | M10: -1.4210855e-14 | N10: 1.4210855e-14 | O10: 1.834375 | P10: 0.027765527 | Q10: 59.984375 | R10: h0.300_o60 | S10: 0.3 | T10: 60 | U10: 60 | V10: 0.025885941 | W10: 6.7694922 | X10: 63.453125 | Y10: 60 | Z10: 0.3 | AA10: 9.0312973 | AB10: 63.40625 | AC10: 74.528061 | AD10: 83.559358 | AE10: 0.24659627 | AF10: 18.659184 | AG10: -2.0620922e-11 | AH10: 2.4605557e-13 | AI10: FALSE | AJ10: FALSE | AK10: TRUE | AL10: 0.36285225 | AM10: FALSE
A11: 25mm_uniform | B11: 25 | C11: uniform | D11: 1.875 | E11: 30 | F11: 98 | G11: 10 | H11: 0.62 | I11: 25 | J11: 78.805955 | K11: 5 | L11: 83.805955 | M11: -1.4210855e-14 | N11: 1.4210855e-14 | O11: 1.834375 | P11: 0.027765527 | Q11: 59.984375 | R11: h0.300_o80 | S11: 0.3 | T11: 60 | U11: 80 | V11: 0.01715569 | W11: 38.212263 | X11: 69.765625 | Y11: 60 | Z11: 0.3 | AA11: 1.0698561 | AB11: 69.71875 | AC11: 82.602557 | AD11: 83.672413 | AE11: 0.13354152 | AF11: 13.489132 | AG11: -5.601461e-11 | AH11: 6.683846e-13 | AI11: FALSE | AJ11: FALSE | AK11: TRUE | AL11: 0.35652183 | AM11: FALSE
A12: 25mm_uniform | B12: 25 | C12: uniform | D12: 1.875 | E12: 30 | F12: 98 | G12: 10 | H12: 0.62 | I12: 25 | J12: 78.805955 | K12: 5 | L12: 83.805955 | M12: -1.4210855e-14 | N12: 1.4210855e-14 | O12: 1.834375 | P12: 0.027765527 | Q12: 59.984375 | R12: h0.300_o100 | S12: 0.3 | T12: 60 | U12: 100 | V12: 0.012766288 | W12: 54.021086 | X12: 72.015625 | Y12: 53.427599 | Z12: 0.26713799 | AA12: 0 | AC12: 83.721958 | AD12: 83.721958 | AE12: 0.08399693 | AF12: 10.462674 | AG12: -2.2722935e-12 | AH12: 2.7113747e-14 | AI12: TRUE | AJ12: TRUE | AK12: TRUE | AL12: 0.36117225 | AM12: TRUE
A13: 25mm_uniform | B13: 25 | C13: uniform | D13: 1.875 | E13: 30 | F13: 98 | G13: 10 | H13: 0.62 | I13: 25 | J13: 78.805955 | K13: 5 | L13: 83.805955 | M13: -1.4210855e-14 | N13: 1.4210855e-14 | O13: 1.834375 | P13: 0.027765527 | Q13: 59.984375 | R13: h0.450_o40 | S13: 0.45 | T13: 90 | U13: 40 | V13: 0.0026338248 | W13: 90.514047 | X13: 81.703125 | Y13: 75.902139 | Z13: 0.37951069 | AA13: 0 | AC13: 83.037645 | AD13: 83.037645 | AE13: 0.76831016 | AF13: 27.137915 | AG13: -2.3500091e-12 | AH13: 2.8041075e-14 | AI13: TRUE | AJ13: TRUE | AK13: FALSE | AL13: 0.35050579 | AM13: FALSE
A14: 25mm_uniform | B14: 25 | C14: uniform | D14: 1.875 | E14: 30 | F14: 98 | G14: 10 | H14: 0.62 | I14: 25 | J14: 78.805955 | K14: 5 | L14: 83.805955 | M14: -1.4210855e-14 | N14: 1.4210855e-14 | O14: 1.834375 | P14: 0.027765527 | Q14: 59.984375 | R14: h0.450_o60 | S14: 0.45 | T14: 90 | U14: 60 | V14: 0.0055368069 | W14: 80.0587 | X14: 77.109375 | Y14: 68.797263 | Z14: 0.34398632 | AA14: 0 | AC14: 83.551463 | AD14: 83.551463 | AE14: 0.25449167 | AF14: 15.720141 | AG14: -2.7442548e-11 | AH14: 3.2745344e-13 | AI14: TRUE | AJ14: TRUE | AK14: TRUE | AL14: 0.36494563 | AM14: TRUE
A15: 25mm_uniform | B15: 25 | C15: uniform | D15: 1.875 | E15: 30 | F15: 98 | G15: 10 | H15: 0.62 | I15: 25 | J15: 78.805955 | K15: 5 | L15: 83.805955 | M15: -1.4210855e-14 | N15: 1.4210855e-14 | O15: 1.834375 | P15: 0.027765527 | Q15: 59.984375 | R15: h0.450_o80 | S15: 0.45 | T15: 90 | U15: 80 | V15: 0.0090421999 | W15: 67.433717 | X15: 74.203125 | Y15: 61.053136 | Z15: 0.30526568 | AA15: 0 | AC15: 83.672126 | AD15: 83.672126 | AE15: 0.1338285 | AF15: 10.978476 | AG15: -6.6061906e-11 | AH15: 7.8827222e-13 | AI15: TRUE | AJ15: TRUE | AK15: TRUE | AL15: 0.36616642 | AM15: TRUE
A16: 25mm_uniform | B16: 25 | C16: uniform | D16: 1.875 | E16: 30 | F16: 98 | G16: 10 | H16: 0.62 | I16: 25 | J16: 78.805955 | K16: 5 | L16: 83.805955 | M16: -1.4210855e-14 | N16: 1.4210855e-14 | O16: 1.834375 | P16: 0.027765527 | Q16: 59.984375 | R16: h0.450_o100 | S16: 0.45 | T16: 90 | U16: 100 | V16: 0.012766288 | W16: 54.021086 | X16: 72.015625 | Y16: 53.427599 | Z16: 0.26713799 | AA16: 0 | AC16: 83.721958 | AD16: 83.721958 | AE16: 0.08399693 | AF16: 8.4289169 | AG16: -2.2722935e-12 | AH16: 2.7113747e-14 | AI16: TRUE | AJ16: TRUE | AK16: TRUE | AL16: 0.35860162 | AM16: TRUE
A17: 25mm_uniform | B17: 25 | C17: uniform | D17: 1.875 | E17: 30 | F17: 98 | G17: 10 | H17: 0.62 | I17: 25 | J17: 78.805955 | K17: 5 | L17: 83.805955 | M17: -1.4210855e-14 | N17: 1.4210855e-14 | O17: 1.834375 | P17: 0.027765527 | Q17: 59.984375 | R17: h0.600_o40 | S17: 0.6 | T17: 120 | U17: 40 | V17: 0.0026338248 | W17: 90.514047 | X17: 81.703125 | Y17: 75.902139 | Z17: 0.37951069 | AA17: 0 | AC17: 83.037645 | AD17: 83.037645 | AE17: 0.76831016 | AF17: 24.107138 | AG17: -2.3500091e-12 | AH17: 2.8041075e-14 | AI17: TRUE | AJ17: TRUE | AK17: FALSE | AL17: 0.35382842 | AM17: FALSE
A18: 25mm_uniform | B18: 25 | C18: uniform | D18: 1.875 | E18: 30 | F18: 98 | G18: 10 | H18: 0.62 | I18: 25 | J18: 78.805955 | K18: 5 | L18: 83.805955 | M18: -1.4210855e-14 | N18: 1.4210855e-14 | O18: 1.834375 | P18: 0.027765527 | Q18: 59.984375 | R18: h0.600_o60 | S18: 0.6 | T18: 120 | U18: 60 | V18: 0.0055368069 | W18: 80.0587 | X18: 77.109375 | Y18: 68.797263 | Z18: 0.34398632 | AA18: 0 | AC18: 83.551463 | AD18: 83.551463 | AE18: 0.25449167 | AF18: 13.699585 | AG18: -2.7442548e-11 | AH18: 3.2745344e-13 | AI18: TRUE | AJ18: TRUE | AK18: TRUE | AL18: 0.35436379 | AM18: TRUE
A19: 25mm_uniform | B19: 25 | C19: uniform | D19: 1.875 | E19: 30 | F19: 98 | G19: 10 | H19: 0.62 | I19: 25 | J19: 78.805955 | K19: 5 | L19: 83.805955 | M19: -1.4210855e-14 | N19: 1.4210855e-14 | O19: 1.834375 | P19: 0.027765527 | Q19: 59.984375 | R19: h0.600_o80 | S19: 0.6 | T19: 120 | U19: 80 | V19: 0.0090421999 | W19: 67.433717 | X19: 74.203125 | Y19: 61.053136 | Z19: 0.30526568 | AA19: 0 | AC19: 83.672126 | AD19: 83.672126 | AE19: 0.1338285 | AF19: 9.4630311 | AG19: -6.6061906e-11 | AH19: 7.8827222e-13 | AI19: TRUE | AJ19: TRUE | AK19: TRUE | AL19: 0.35453825 | AM19: TRUE
A20: 25mm_uniform | B20: 25 | C20: uniform | D20: 1.875 | E20: 30 | F20: 98 | G20: 10 | H20: 0.62 | I20: 25 | J20: 78.805955 | K20: 5 | L20: 83.805955 | M20: -1.4210855e-14 | N20: 1.4210855e-14 | O20: 1.834375 | P20: 0.027765527 | Q20: 59.984375 | R20: h0.600_o100 | S20: 0.6 | T20: 120 | U20: 100 | V20: 0.012766288 | W20: 54.021086 | X20: 72.015625 | Y20: 53.427599 | Z20: 0.26713799 | AA20: 0 | AC20: 83.721958 | AD20: 83.721958 | AE20: 0.08399693 | AF20: 7.2165385 | AG20: -2.2722935e-12 | AH20: 2.7113747e-14 | AI20: TRUE | AJ20: TRUE | AK20: TRUE | AL20: 0.36297871 | AM20: TRUE
A21: 25mm_uniform | B21: 25 | C21: uniform | D21: 1.875 | E21: 30 | F21: 98 | G21: 10 | H21: 0.62 | I21: 25 | J21: 78.805955 | K21: 5 | L21: 83.805955 | M21: -1.4210855e-14 | N21: 1.4210855e-14 | O21: 1.834375 | P21: 0.027765527 | Q21: 59.984375 | R21: h0.750_o40 | S21: 0.75 | T21: 150 | U21: 40 | V21: 0.0026338248 | W21: 90.514047 | X21: 81.703125 | Y21: 75.902139 | Z21: 0.37951069 | AA21: 0 | AC21: 83.037645 | AD21: 83.037645 | AE21: 0.76831016 | AF21: 22.038824 | AG21: -2.3500091e-12 | AH21: 2.8041075e-14 | AI21: TRUE | AJ21: TRUE | AK21: TRUE | AL21: 0.35333121 | AM21: TRUE
A22: 25mm_uniform | B22: 25 | C22: uniform | D22: 1.875 | E22: 30 | F22: 98 | G22: 10 | H22: 0.62 | I22: 25 | J22: 78.805955 | K22: 5 | L22: 83.805955 | M22: -1.4210855e-14 | N22: 1.4210855e-14 | O22: 1.834375 | P22: 0.027765527 | Q22: 59.984375 | R22: h0.750_o60 | S22: 0.75 | T22: 150 | U22: 60 | V22: 0.0055368069 | W22: 80.0587 | X22: 77.109375 | Y22: 68.797263 | Z22: 0.34398632 | AA22: 0 | AC22: 83.551463 | AD22: 83.551463 | AE22: 0.25449167 | AF22: 12.32068 | AG22: -2.7442548e-11 | AH22: 3.2745344e-13 | AI22: TRUE | AJ22: TRUE | AK22: TRUE | AL22: 0.35912238 | AM22: TRUE
A23: 25mm_uniform | B23: 25 | C23: uniform | D23: 1.875 | E23: 30 | F23: 98 | G23: 10 | H23: 0.62 | I23: 25 | J23: 78.805955 | K23: 5 | L23: 83.805955 | M23: -1.4210855e-14 | N23: 1.4210855e-14 | O23: 1.834375 | P23: 0.027765527 | Q23: 59.984375 | R23: h0.750_o80 | S23: 0.75 | T23: 150 | U23: 80 | V23: 0.0090421999 | W23: 67.433717 | X23: 74.203125 | Y23: 61.053136 | Z23: 0.30526568 | AA23: 0 | AC23: 83.672126 | AD23: 83.672126 | AE23: 0.1338285 | AF23: 8.4288305 | AG23: -6.6061906e-11 | AH23: 7.8827222e-13 | AI23: TRUE | AJ23: TRUE | AK23: TRUE | AL23: 0.35992825 | AM23: TRUE
... A28: 25mm_uniform | B28: 25 | C28: uniform | D28: 1.875 | E28: 30 | F28: 98 | G28: 10 | H28: 0.62 | I28: 25 | J28: 78.805955 | K28: 5 | L28: 83.805955 | M28: -1.4210855e-14 | N28: 1.4210855e-14 | O28: 1.834375 | P28: 0.027765527 | Q28: 59.984375 | R28: h0.900_o100 | S28: 0.9 | T28: 180 | U28: 100 | V28: 0.012766288 | W28: 54.021086 | X28: 72.015625 | Y28: 53.427599 | Z28: 0.26713799 | AA28: 0 | AC28: 83.721958 | AD28: 83.721958 | AE28: 0.08399693 | AF28: 5.7784087 | AG28: -2.2722935e-12 | AH28: 2.7113747e-14 | AI28: TRUE | AJ28: TRUE | AK28: TRUE | AL28: 0.36729354 | AM28: TRUE
A29: 25mm_front_loaded | B29: 25 | C29: front_loaded | D29: 1.875 | E29: 60 | F29: 98 | G29: 10 | H29: 0.62 | I29: 25 | J29: 78.805955 | K29: 5 | L29: 83.805955 | M29: 0 | N29: -1.4210855e-14 | O29: 1.834375 | P29: 0.032681434 | Q29: 28.703125 | R29: h0.150_o40 | S29: 0.15 | T29: 30 | U29: 40 | V29: 0.032635332 | W29: 0.14106473 | X29: 29.828125 | Y29: 30 | Z29: 0.15 | AA29: 47.640281 | AB29: 29.78125 | AC29: 36.040204 | AD29: 83.680486 | AE29: 0.12546897 | AF29: 37.595231 | AG29: -5.1447735e-13 | AH29: 6.1389116e-15 | AI29: FALSE | AJ29: FALSE | AK29: FALSE | AL29: 1.0793422 | AM29: FALSE
A30: 25mm_front_loaded | B30: 25 | C30: front_loaded | D30: 1.875 | E30: 30 | F30: 98 | G30: 10 | H30: 0.62 | I30: 25 | J30: 78.805955 | K30: 5 | L30: 83.805955 | M30: 0 | N30: -1.4210855e-14 | O30: 1.834375 | P30: 0.032681434 | Q30: 28.703125 | R30: h0.150_o60 | S30: 0.15 | T30: 30 | U30: 60 | V30: 0.032190318 | W30: 1.5027386 | X30: 30.359375 | Y30: 30 | Z30: 0.15 | AA30: 41.649551 | AB30: 30.3125 | AC30: 41.940974 | AD30: 83.590525 | AE30: 0.21542999 | AF30: 24.296332 | AG30: 1.1384227e-12 | AH30: 1.3584031e-14 | AI30: FALSE | AJ30: FALSE | AK30: FALSE | AL30: 0.34513567 | AM30: FALSE
A31: 25mm_front_loaded | B31: 25 | C31: front_loaded | D31: 1.875 | E31: 30 | F31: 98 | G31: 10 | H31: 0.62 | I31: 25 | J31: 78.805955 | K31: 5 | L31: 83.805955 | M31: 0 | N31: -1.4210855e-14 | O31: 1.834375 | P31: 0.032681434 | Q31: 28.703125 | R31: h0.150_o80 | S31: 0.15 | T31: 30 | U31: 80 | V31: 0.032101911 | W31: 1.7732474 | X31: 31.046875 | Y31: 30 | Z31: 0.15 | AA31: 34.634176 | AB31: 31 | AC31: 49.048446 | AD31: 83.682622 | AE31: 0.12333229 | AF31: 18.036161 | AG31: 3.5423608e-11 | AH31: 4.2268606e-13 | AI31: FALSE | AJ31: FALSE | AK31: TRUE | AL31: 0.362346 | AM31: FALSE
A32: 25mm_front_loaded | B32: 25 | C32: front_loaded | D32: 1.875 | E32: 30 | F32: 98 | G32: 10 | H32: 0.62 | I32: 25 | J32: 78.805955 | K32: 5 | L32: 83.805955 | M32: 0 | N32: -1.4210855e-14 | O32: 1.834375 | P32: 0.032681434 | Q32: 28.703125 | R32: h0.150_o100 | S32: 0.15 | T32: 30 | U32: 100 | V32: 0.031963627 | W32: 2.1963745 | X32: 31.859375 | Y32: 30 | Z32: 0.15 | AA32: 27.230376 | AB32: 31.8125 | AC32: 56.495295 | AD32: 83.725671 | AE32: 0.08028355 | AF32: 14.376036 | AG32: 1.7930291e-10 | AH32: 2.1395008e-12 | AI32: FALSE | AJ32: FALSE | AK32: TRUE | AL32: 0.351368 | AM32: FALSE
A33: 25mm_front_loaded | B33: 25 | C33: front_loaded | D33: 1.875 | E33: 60 | F33: 98 | G33: 10 | H33: 0.62 | I33: 25 | J33: 78.805955 | K33: 5 | L33: 83.805955 | M33: 0 | N33: -1.4210855e-14 | O33: 1.834375 | P33: 0.032681434 | Q33: 28.703125 | R33: h0.300_o40 | S33: 0.3 | T33: 60 | U33: 40 | V33: 0.022614818 | W33: 30.802248 | X33: 48.765625 | Y33: 60 | Z33: 0.3 | AA33: 15.89754 | AB33: 48.71875 | AC33: 67.763412 | AD33: 83.660952 | AE33: 0.14500306 | AF33: 30.347597 | AG33: -1.0046686e-12 | AH33: 1.1988033e-14 | AI33: FALSE | AJ33: FALSE | AK33: FALSE | AL33: 1.1096395 | AM33: FALSE
A34: 25mm_front_loaded | B34: 25 | C34: front_loaded | D34: 1.875 | E34: 30 | F34: 98 | G34: 10 | H34: 0.62 | I34: 25 | J34: 78.805955 | K34: 5 | L34: 83.805955 | M34: 0 | N34: -1.4210855e-14 | O34: 1.834375 | P34: 0.032681434 | Q34: 28.703125 | R34: h0.300_o60 | S34: 0.3 | T34: 60 | U34: 60 | V34: 0.019631553 | W34: 39.930564 | X34: 52.421875 | Y34: 60 | Z34: 0.3 | AA34: 8.2470742 | AB34: 52.375 | AC34: 75.314076 | AD34: 83.56115 | AE34: 0.24480473 | AF34: 18.553951 | AG34: -2.0485114e-11 | AH34: 2.4443506e-13 | AI34: FALSE | AJ34: FALSE | AK34: TRUE | AL34: 0.36229288 | AM34: FALSE
A35: 25mm_front_loaded | B35: 25 | C35: front_loaded | D35: 1.875 | E35: 30 | F35: 98 | G35: 10 | H35: 0.62 | I35: 25 | J35: 78.805955 | K35: 5 | L35: 83.805955 | M35: 0 | N35: -1.4210855e-14 | O35: 1.834375 | P35: 0.032681434 | Q35: 28.703125 | R35: h0.300_o80 | S35: 0.3 | T35: 60 | U35: 80 | V35: 0.008923713 | W35: 72.694855 | X35: 66.328125 | Y35: 59.677189 | Z35: 0.29838595 | AA35: 0 | AC35: 83.673499 | AD35: 83.673499 | AE35: 0.13245596 | AF35: 13.36905 | AG35: -7.3243606e-11 | AH35: 8.739666e-13 | AI35: TRUE | AJ35: TRUE | AK35: TRUE | AL35: 0.38721042 | AM35: TRUE
A36: 25mm_front_loaded | B36: 25 | C36: front_loaded | D36: 1.875 | E36: 30 | F36: 98 | G36: 10 | H36: 0.62 | I36: 25 | J36: 78.805955 | K36: 5 | L36: 83.805955 | M36: 0 | N36: -1.4210855e-14 | O36: 1.834375 | P36: 0.032681434 | Q36: 28.703125 | R36: h0.300_o100 | S36: 0.3 | T36: 60 | U36: 100 | V36: 0.012519814 | W36: 61.691358 | X36: 61.421875 | Y36: 51.782081 | Z36: 0.25891041 | AA36: 0 | AC36: 83.722837 | AD36: 83.722837 | AE36: 0.083117313 | AF36: 10.306358 | AG36: -2.0714611e-11 | AH36: 2.4717349e-13 | AI36: TRUE | AJ36: TRUE | AK36: TRUE | AL36: 0.36255667 | AM36: TRUE
A37: 25mm_front_loaded | B37: 25 | C37: front_loaded | D37: 1.875 | E37: 30 | F37: 98 | G37: 10 | H37: 0.62 | I37: 25 | J37: 78.805955 | K37: 5 | L37: 83.805955 | M37: 0 | N37: -1.4210855e-14 | O37: 1.834375 | P37: 0.032681434 | Q37: 28.703125 | R37: h0.450_o40 | S37: 0.45 | T37: 90 | U37: 40 | V37: 0.0026275197 | W37: 91.960207 | X37: 75.359375 | Y37: 75.558481 | Z37: 0.3777924 | AA37: 0 | AC37: 83.046414 | AD37: 83.046414 | AE37: 0.75954087 | AF37: 26.99698 | AG37: -3.0234704e-12 | AH37: 3.6077035e-14 | AI37: TRUE | AJ37: TRUE | AK37: FALSE | AL37: 0.36318804 | AM37: FALSE
A38: 25mm_front_loaded | B38: 25 | C38: front_loaded | D38: 1.875 | E38: 30 | F38: 98 | G38: 10 | H38: 0.62 | I38: 25 | J38: 78.805955 | K38: 5 | L38: 83.805955 | M38: 0 | N38: -1.4210855e-14 | O38: 1.834375 | P38: 0.032681434 | Q38: 28.703125 | R38: h0.450_o60 | S38: 0.45 | T38: 90 | U38: 60 | V38: 0.0055001856 | W38: 83.170305 | X38: 70.640625 | Y38: 67.970579 | Z38: 0.33985289 | AA38: 0 | AC38: 83.554069 | AD38: 83.554069 | AE38: 0.25188528 | AF38: 15.573785 | AG38: -2.6892155e-11 | AH38: 3.2088597e-13 | AI38: TRUE | AJ38: TRUE | AK38: TRUE | AL38: 0.38267271 | AM38: TRUE
A39: 25mm_front_loaded | B39: 25 | C39: front_loaded | D39: 1.875 | E39: 30 | F39: 98 | G39: 10 | H39: 0.62 | I39: 25 | J39: 78.805955 | K39: 5 | L39: 83.805955 | M39: 0 | N39: -1.4210855e-14 | O39: 1.834375 | P39: 0.032681434 | Q39: 28.703125 | R39: h0.450_o80 | S39: 0.45 | T39: 90 | U39: 80 | V39: 0.008923713 | W39: 72.694855 | X39: 66.328125 | Y39: 59.677189 | Z39: 0.29838595 | AA39: 0 | AC39: 83.673499 | AD39: 83.673499 | AE39: 0.13245596 | AF39: 10.826894 | AG39: -7.3243606e-11 | AH39: 8.739666e-13 | AI39: TRUE | AJ39: TRUE | AK39: TRUE | AL39: 0.38163679 | AM39: TRUE
A40: 25mm_front_loaded | B40: 25 | C40: front_loaded | D40: 1.875 | E40: 30 | F40: 98 | G40: 10 | H40: 0.62 | I40: 25 | J40: 78.805955 | K40: 5 | L40: 83.805955 | M40: 0 | N40: -1.4210855e-14 | O40: 1.834375 | P40: 0.032681434 | Q40: 28.703125 | R40: h0.450_o100 | S40: 0.45 | T40: 90 | U40: 100 | V40: 0.012519814 | W40: 61.691358 | X40: 61.421875 | Y40: 51.782081 | Z40: 0.25891041 | AA40: 0 | AC40: 83.722837 | AD40: 83.722837 | AE40: 0.083117313 | AF40: 8.2726007 | AG40: -2.0714611e-11 | AH40: 2.4717349e-13 | AI40: TRUE | AJ40: TRUE | AK40: TRUE | AL40: 0.36381146 | AM40: TRUE
A41: 25mm_front_loaded | B41: 25 | C41: front_loaded | D41: 1.875 | E41: 30 | F41: 98 | G41: 10 | H41: 0.62 | I41: 25 | J41: 78.805955 | K41: 5 | L41: 83.805955 | M41: 0 | N41: -1.4210855e-14 | O41: 1.834375 | P41: 0.032681434 | Q41: 28.703125 | R41: h0.600_o40 | S41: 0.6 | T41: 120 | U41: 40 | V41: 0.0026275197 | W41: 91.960207 | X41: 75.359375 | Y41: 75.558481 | Z41: 0.3777924 | AA41: 0 | AC41: 83.046414 | AD41: 83.046414 | AE41: 0.75954087 | AF41: 23.966203 | AG41: -3.0234704e-12 | AH41: 3.6077035e-14 | AI41: TRUE | AJ41: TRUE | AK41: TRUE | AL41: 0.36215583 | AM41: TRUE
A42: 25mm_front_loaded | B42: 25 | C42: front_loaded | D42: 1.875 | E42: 30 | F42: 98 | G42: 10 | H42: 0.62 | I42: 25 | J42: 78.805955 | K42: 5 | L42: 83.805955 | M42: 0 | N42: -1.4210855e-14 | O42: 1.834375 | P42: 0.032681434 | Q42: 28.703125 | R42: h0.600_o60 | S42: 0.6 | T42: 120 | U42: 60 | V42: 0.0055001856 | W42: 83.170305 | X42: 70.640625 | Y42: 67.970579 | Z42: 0.33985289 | AA42: 0 | AC42: 83.554069 | AD42: 83.554069 | AE42: 0.25188528 | AF42: 13.55323 | AG42: -2.6892155e-11 | AH42: 3.2088597e-13 | AI42: TRUE | AJ42: TRUE | AK42: TRUE | AL42: 0.37146888 | AM42: TRUE
A43: 25mm_front_loaded | B43: 25 | C43: front_loaded | D43: 1.875 | E43: 30 | F43: 98 | G43: 10 | H43: 0.62 | I43: 25 | J43: 78.805955 | K43: 5 | L43: 83.805955 | M43: 0 | N43: -1.4210855e-14 | O43: 1.834375 | P43: 0.032681434 | Q43: 28.703125 | R43: h0.600_o80 | S43: 0.6 | T43: 120 | U43: 80 | V43: 0.008923713 | W43: 72.694855 | X43: 66.328125 | Y43: 59.677189 | Z43: 0.29838595 | AA43: 0 | AC43: 83.673499 | AD43: 83.673499 | AE43: 0.13245596 | AF43: 9.3114487 | AG43: -7.3243606e-11 | AH43: 8.739666e-13 | AI43: TRUE | AJ43: TRUE | AK43: TRUE | AL43: 0.36671683 | AM43: TRUE
A44: 25mm_front_loaded | B44: 25 | C44: front_loaded | D44: 1.875 | E44: 30 | F44: 98 | G44: 10 | H44: 0.62 | I44: 25 | J44: 78.805955 | K44: 5 | L44: 83.805955 | M44: 0 | N44: -1.4210855e-14 | O44: 1.834375 | P44: 0.032681434 | Q44: 28.703125 | R44: h0.600_o100 | S44: 0.6 | T44: 120 | U44: 100 | V44: 0.012519814 | W44: 61.691358 | X44: 61.421875 | Y44: 51.782081 | Z44: 0.25891041 | AA44: 0 | AC44: 83.722837 | AD44: 83.722837 | AE44: 0.083117313 | AF44: 7.0602223 | AG44: -2.0714611e-11 | AH44: 2.4717349e-13 | AI44: TRUE | AJ44: TRUE | AK44: TRUE | AL44: 0.39406625 | AM44: TRUE
A45: 25mm_front_loaded | B45: 25 | C45: front_loaded | D45: 1.875 | E45: 30 | F45: 98 | G45: 10 | H45: 0.62 | I45: 25 | J45: 78.805955 | K45: 5 | L45: 83.805955 | M45: 0 | N45: -1.4210855e-14 | O45: 1.834375 | P45: 0.032681434 | Q45: 28.703125 | R45: h0.750_o40 | S45: 0.75 | T45: 150 | U45: 40 | V45: 0.0026275197 | W45: 91.960207 | X45: 75.359375 | Y45: 75.558481 | Z45: 0.3777924 | AA45: 0 | AC45: 83.046414 | AD45: 83.046414 | AE45: 0.75954087 | AF45: 21.897889 | AG45: -3.0234704e-12 | AH45: 3.6077035e-14 | AI45: TRUE | AJ45: TRUE | AK45: TRUE | AL45: 0.36959563 | AM45: TRUE
...

Sheet Design selection
A1: Compare every tested design
A2: All storm shapes at the design depth must pass. Lowest capacity wins; shortest worst drawdown breaks a capacity tie.
A4: design_id | B4: capacity_m3 | C4: storage_depth_m | D4: outlet_side_mm | E4: all_design_storms_pass | F4: worst_peak_reduction_pct | G4: worst_overflow_m3 | H4: worst_drawdown_h | I4: passing_shapes
A5: h0.150_o40 | B5: 30 | C5: 0.15 | D5: 40 | E5: FALSE | F5: -1.0880186e-12 | G5: 150.51815 | H5: 37.810482 | I5: 0
A6: h0.150_o60 | B6: 30 | C6: 0.15 | D6: 60 | E6: FALSE | F6: -1.0880186e-12 | G6: 143.96558 | H6: 24.518629 | I6: 0
A7: h0.150_o80 | B7: 30 | C7: 0.15 | D7: 80 | E7: FALSE | F7: -1.0880186e-12 | G7: 136.19508 | H7: 18.261567 | I7: 0
A8: h0.150_o100 | B8: 30 | C8: 0.15 | D8: 100 | E8: FALSE | F8: -1.0880186e-12 | G8: 127.75316 | H8: 14.606208 | I8: 0
A9: h0.300_o40 | B9: 60 | C9: 0.3 | D9: 40 | E9: FALSE | F9: 9.7699626e-13 | G9: 118.35782 | H9: 30.567234 | I9: 0
A10: h0.300_o60 | B10: 60 | C10: 0.3 | D10: 60 | E10: FALSE | F10: 9.7699626e-13 | G10: 109.49027 | H10: 18.778817 | I10: 0
A11: h0.300_o80 | B11: 60 | C11: 0.3 | D11: 80 | E11: FALSE | F11: 9.7699626e-13 | G11: 98.708263 | H11: 13.610632 | I11: 0
A12: h0.300_o100 | B12: 60 | C12: 0.3 | D12: 100 | E12: FALSE | F12: 9.7699626e-13 | G12: 86.586113 | H12: 10.715497 | I12: 0
A13: h0.450_o40 | B13: 90 | C13: 0.45 | D13: 40 | E13: FALSE | F13: -3.4416914e-12 | G13: 87.08161 | H13: 28.666003 | I13: 0
A14: h0.450_o60 | B14: 90 | C14: 0.45 | D14: 60 | E14: FALSE | F14: -3.4416914e-12 | G14: 76.994624 | H14: 16.812562 | I14: 0
A15: h0.450_o80 | B15: 90 | C15: 0.45 | D15: 80 | E15: FALSE | F15: -3.4416914e-12 | G15: 64.799683 | H15: 11.871001 | I15: 0
A16: h0.450_o100 | B16: 90 | C16: 0.45 | D16: 100 | E16: FALSE | F16: -3.4416914e-12 | G16: 51.218766 | H16: 9.1943515 | I16: 0
... A28: h0.900_o100 | B28: 180 | C28: 0.9 | D28: 100 | E28: TRUE | F28: 63.088748 | G28: 0 | H28: 7.1952375 | I28: 3

Sheet Sensitivity
A1: One-at-a-time sensitivity
A2: Only the named parameter changes. Matching baseline runoff is recomputed for CN and lag changes; nominal rows repeat intentionally in each parameter group.
A4: event_id | B4: rainfall_mm | C4: shape | D4: dt_s | E4: horizon_h | F4: curve_number | G4: lag_min | H4: discharge_coefficient | I4: rainfall_total_mm | J4: parking_runoff_m3 | K4: direct_rain_m3 | L4: total_inflow_m3 | M4: runoff_generation_error_m3 | N4: transform_error_m3 | O4: inflow_tail_end_h | P4: baseline_peak_m3_s | Q4: baseline_time_to_peak_min | R4: design_id | S4: storage_depth_m | T4: capacity_m3 | U4: outlet_side_mm | V4: peak_downstream_m3_s | W4: peak_reduction_pct | X4: time_to_peak_min | Y4: maximum_storage_m3 | Z4: maximum_depth_m | AA4: overflow_m3 | AB4: overflow_onset_min | AC4: controlled_discharge_m3 | AD4: total_discharge_m3 | AE4: residual_storage_m3 | AF4: drawdown_h_after_rain | AG4: routing_balance_error_m3 | AH4: routing_balance_relative_error | AI4: peak_pass | AJ4: overflow_pass | AK4: drawdown_pass | AL4: simulation_runtime_s | AM4: all_pass | AN4: varied_parameter | AO4: parameter_value | AP4: is_nominal
A5: 50mm_uniform | B5: 50 | C5: uniform | D5: 1.875 | E5: 30 | F5: 95 | G5: 10 | H5: 0.62 | I5: 50 | J5: 147.60951 | K5: 10 | L5: 157.60951 | M5: 0 | N5: 0 | O5: 1.834375 | P5: 0.054140092 | Q5: 59.984375 | R5: h0.750_o100 | S5: 0.75 | T5: 150 | U5: 100 | V5: 0.019290764 | W5: 64.3688 | X5: 73.671875 | Y5: 108.80214 | Z5: 0.5440107 | AA5: 0 | AC5: 157.51964 | AD5: 157.51964 | AE5: 0.089873183 | AF5: 7.373844 | AG5: -4.6087524e-10 | AH5: 2.9241587e-12 | AI5: TRUE | AJ5: TRUE | AK5: TRUE | AL5: 0.38537754 | AM5: TRUE | AN5: curve_number | AO5: 95 | AP5: FALSE
A6: 50mm_front_loaded | B6: 50 | C6: front_loaded | D6: 1.875 | E6: 30 | F6: 95 | G6: 10 | H6: 0.62 | I6: 50 | J6: 147.60951 | K6: 10 | L6: 157.60951 | M6: 0 | N6: 2.8421709e-14 | O6: 1.834375 | P6: 0.061425244 | Q6: 29.984375 | R6: h0.750_o100 | S6: 0.75 | T6: 150 | U6: 100 | V6: 0.019014 | W6: 69.045299 | X6: 65.296875 | Y6: 105.99234 | Z6: 0.52996172 | AA6: 0 | AC6: 157.52059 | AD6: 157.52059 | AE6: 0.088929681 | AF6: 7.2223443 | AG6: -4.8327725e-10 | AH6: 3.0662949e-12 | AI6: TRUE | AJ6: TRUE | AK6: TRUE | AL6: 0.38594858 | AM6: TRUE | AN6: curve_number | AO6: 95 | AP6: FALSE
A7: 50mm_back_loaded | B7: 50 | C7: back_loaded | D7: 1.875 | E7: 30 | F7: 95 | G7: 10 | H7: 0.62 | I7: 50 | J7: 147.60951 | K7: 10 | L7: 157.60951 | M7: 0 | N7: 0 | O7: 1.834375 | P7: 0.079158361 | Q7: 59.984375 | R7: h0.750_o100 | S7: 0.75 | T7: 150 | U7: 100 | V7: 0.019998376 | W7: 74.736243 | X7: 76.390625 | Y7: 116.17128 | Z7: 0.58085642 | AA7: 0 | AC7: 157.51869 | AD7: 157.51869 | AE7: 0.090822019 | AF7: 7.5238134 | AG7: -4.476732e-10 | AH7: 2.8403945e-12 | AI7: TRUE | AJ7: TRUE | AK7: TRUE | AL7: 0.38578729 | AM7: TRUE | AN7: curve_number | AO7: 95 | AP7: FALSE
A8: 50mm_uniform | B8: 50 | C8: uniform | D8: 1.875 | E8: 30 | F8: 98 | G8: 10 | H8: 0.62 | I8: 50 | J8: 177.10337 | K8: 10 | L8: 187.10337 | M8: 0 | N8: 0 | O8: 1.834375 | P8: 0.05747879 | Q8: 59.984375 | R8: h0.750_o100 | S8: 0.75 | T8: 150 | U8: 100 | V8: 0.021216141 | W8: 63.088748 | X8: 73.390625 | Y8: 129.47654 | Z8: 0.64738271 | AA8: 0 | AC8: 187.01172 | AD8: 187.01172 | AE8: 0.091649252 | AF8: 7.6526577 | AG8: -5.9858525e-10 | AH8: 3.1992222e-12 | AI8: TRUE | AJ8: TRUE | AK8: TRUE | AL8: 0.36809358 | AM8: TRUE | AN8: curve_number | AO8: 98 | AP8: TRUE
A9: 50mm_front_loaded | B9: 50 | C9: front_loaded | D9: 1.875 | E9: 30 | F9: 98 | G9: 10 | H9: 0.62 | I9: 50 | J9: 177.10337 | K9: 10 | L9: 187.10337 | M9: 0 | N9: 0 | O9: 1.834375 | P9: 0.073191362 | Q9: 26.234375 | R9: h0.750_o100 | S9: 0.75 | T9: 150 | U9: 100 | V9: 0.021044243 | W9: 71.247641 | X9: 64.578125 | Y9: 127.55061 | Z9: 0.63775305 | AA9: 0 | AC9: 187.01261 | AD9: 187.01261 | AE9: 0.09075858 | AF9: 7.5138598 | AG9: -5.9705871e-10 | AH9: 3.1910633e-12 | AI9: TRUE | AJ9: TRUE | AK9: TRUE | AL9: 0.37390933 | AM9: TRUE | AN9: curve_number | AO9: 98 | AP9: TRUE
A10: 50mm_back_loaded | B10: 50 | C10: back_loaded | D10: 1.875 | E10: 30 | F10: 98 | G10: 10 | H10: 0.62 | I10: 50 | J10: 177.10337 | K10: 10 | L10: 187.10337 | M10: 0 | N10: 0 | O10: 1.834375 | P10: 0.085673949 | Q10: 59.984375 | R10: h0.750_o100 | S10: 0.75 | T10: 150 | U10: 100 | V10: 0.021940211 | W10: 74.391036 | X10: 76.171875 | Y10: 137.76136 | Z10: 0.68880682 | AA10: 0 | AC10: 187.01072 | AD10: 187.01072 | AE10: 0.092648516 | AF10: 7.8059894 | AG10: -5.7200612e-10 | AH10: 3.0571663e-12 | AI10: TRUE | AJ10: TRUE | AK10: TRUE | AL10: 0.36891137 | AM10: TRUE | AN10: curve_number | AO10: 98 | AP10: TRUE
A11: 50mm_uniform | B11: 50 | C11: uniform | D11: 1.875 | E11: 30 | F11: 100 | G11: 10 | H11: 0.62 | I11: 50 | J11: 200 | K11: 10 | L11: 210 | M11: 0 | N11: 0 | O11: 1.834375 | P11: 0.058333333 | Q11: 55.265625 | R11: h0.750_o100 | S11: 0.75 | T11: 150 | U11: 100 | V11: 0.02251949 | W11: 61.39516 | X11: 73.109375 | Y11: 144.59009 | Z11: 0.72295044 | AA11: 0 | AC11: 209.90713 | AD11: 209.90713 | AE11: 0.092870756 | AF11: 7.839754 | AG11: -6.7516837e-10 | AH11: 3.2150875e-12 | AI11: TRUE | AJ11: TRUE | AK11: TRUE | AL11: 0.38615383 | AM11: TRUE | AN11: curve_number | AO11: 100 | AP11: FALSE
A12: 50mm_front_loaded | B12: 50 | C12: front_loaded | D12: 1.875 | E12: 30 | F12: 100 | G12: 10 | H12: 0.62 | I12: 50 | J12: 200 | K12: 10 | L12: 210 | M12: 0 | N12: -2.8421709e-14 | O12: 1.834375 | P12: 0.081235443 | Q12: 23.078125 | R12: h0.750_o100 | S12: 0.75 | T12: 150 | U12: 100 | V12: 0.022465263 | W12: 72.345491 | X12: 63.796875 | Y12: 143.94328 | Z12: 0.71971639 | AA12: 0 | AC12: 209.90794 | AD12: 209.90794 | AE12: 0.09205794 | AF12: 7.7156702 | AG12: -6.6862132e-10 | AH12: 3.1839111e-12 | AI12: TRUE | AJ12: TRUE | AK12: TRUE | AL12: 0.37535621 | AM12: TRUE | AN12: curve_number | AO12: 100 | AP12: FALSE
A13: 50mm_back_loaded | B13: 50 | C13: back_loaded | D13: 1.875 | E13: 30 | F13: 100 | G13: 10 | H13: 0.62 | I13: 50 | J13: 200 | K13: 10 | L13: 210 | M13: 0 | N13: 0 | O13: 1.834375 | P13: 0.087515406 | Q13: 59.984375 | R13: h0.750_o100 | S13: 0.75 | T13: 150 | U13: 100 | V13: 0.046160128 | W13: 47.254855 | X13: 71.640625 | Y13: 150 | Z13: 0.75 | AA13: 2.8411034 | AB13: 71.59375 | AC13: 207.06527 | AD13: 209.90637 | AE13: 0.093629336 | AF13: 7.9540974 | AG13: -6.0660096e-10 | AH13: 2.888576e-12 | AI13: FALSE | AJ13: FALSE | AK13: TRUE | AL13: 0.3777525 | AM13: FALSE | AN13: curve_number | AO13: 100 | AP13: FALSE
A14: 50mm_uniform | B14: 50 | C14: uniform | D14: 1.875 | E14: 30 | F14: 98 | G14: 5 | H14: 0.62 | I14: 50 | J14: 177.10337 | K14: 10 | L14: 187.10337 | M14: 0 | N14: 0 | O14: 1.4177083 | P14: 0.057698131 | Q14: 59.984375 | R14: h0.750_o100 | S14: 0.75 | T14: 150 | U14: 100 | V14: 0.021655148 | W14: 62.468199 | X14: 66.640625 | Y14: 134.46641 | Z14: 0.67233206 | AA14: 0 | AC14: 187.01236 | AD14: 187.01236 | AE14: 0.091012039 | AF14: 7.553565 | AG14: -5.8718362e-10 | AH14: 3.1382846e-12 | AI14: TRUE | AJ14: TRUE | AK14: TRUE | AL14: 0.37189542 | AM14: TRUE | AN14: lag_min | AO14: 5 | AP14: FALSE
A15: 50mm_front_loaded | B15: 50 | C15: front_loaded | D15: 1.875 | E15: 30 | F15: 98 | G15: 5 | H15: 0.62 | I15: 50 | J15: 177.10337 | K15: 10 | L15: 187.10337 | M15: 0 | N15: 0 | O15: 1.4177083 | P15: 0.079650305 | Q15: 19.984375 | R15: h0.750_o100 | S15: 0.75 | T15: 150 | U15: 100 | V15: 0.021261688 | W15: 73.306206 | X15: 57.515625 | Y15: 129.98948 | Z15: 0.64994742 | AA15: 0 | AC15: 187.01323 | AD15: 187.01323 | AE15: 0.090142911 | AF15: 7.416717 | AG15: -6.0038932e-10 | AH15: 3.2088643e-12 | AI15: TRUE | AJ15: TRUE | AK15: TRUE | AL15: 0.36884738 | AM15: TRUE | AN15: lag_min | AO15: 5 | AP15: FALSE
A16: 50mm_back_loaded | B16: 50 | C16: back_loaded | D16: 1.875 | E16: 30 | F16: 98 | G16: 5 | H16: 0.62 | I16: 50 | J16: 177.10337 | K16: 10 | L16: 187.10337 | M16: 0 | N16: 0 | O16: 1.4177083 | P16: 0.096581821 | Q16: 59.984375 | R16: h0.750_o100 | S16: 0.75 | T16: 150 | U16: 100 | V16: 0.02253692 | W16: 76.665463 | X16: 68.109375 | Y16: 144.79832 | Z16: 0.72399162 | AA16: 0 | AC16: 187.01136 | AD16: 187.01136 | AE16: 0.092008876 | AF16: 7.7081278 | AG16: -5.6769622e-10 | AH16: 3.0341315e-12 | AI16: TRUE | AJ16: TRUE | AK16: TRUE | AL16: 0.37708137 | AM16: TRUE | AN16: lag_min | AO16: 5 | AP16: FALSE
A17: 50mm_uniform | B17: 50 | C17: uniform | D17: 1.875 | E17: 30 | F17: 98 | G17: 10 | H17: 0.62 | I17: 50 | J17: 177.10337 | K17: 10 | L17: 187.10337 | M17: 0 | N17: 0 | O17: 1.834375 | P17: 0.05747879 | Q17: 59.984375 | R17: h0.750_o100 | S17: 0.75 | T17: 150 | U17: 100 | V17: 0.021216141 | W17: 63.088748 | X17: 73.390625 | Y17: 129.47654 | Z17: 0.64738271 | AA17: 0 | AC17: 187.01172 | AD17: 187.01172 | AE17: 0.091649252 | AF17: 7.6526577 | AG17: -5.9858525e-10 | AH17: 3.1992222e-12 | AI17: TRUE | AJ17: TRUE | AK17: TRUE | AL17: 0.3895985 | AM17: TRUE | AN17: lag_min | AO17: 10 | AP17: TRUE
A18: 50mm_front_loaded | B18: 50 | C18: front_loaded | D18: 1.875 | E18: 30 | F18: 98 | G18: 10 | H18: 0.62 | I18: 50 | J18: 177.10337 | K18: 10 | L18: 187.10337 | M18: 0 | N18: 0 | O18: 1.834375 | P18: 0.073191362 | Q18: 26.234375 | R18: h0.750_o100 | S18: 0.75 | T18: 150 | U18: 100 | V18: 0.021044243 | W18: 71.247641 | X18: 64.578125 | Y18: 127.55061 | Z18: 0.63775305 | AA18: 0 | AC18: 187.01261 | AD18: 187.01261 | AE18: 0.09075858 | AF18: 7.5138598 | AG18: -5.9705871e-10 | AH18: 3.1910633e-12 | AI18: TRUE | AJ18: TRUE | AK18: TRUE | AL18: 0.39767363 | AM18: TRUE | AN18: lag_min | AO18: 10 | AP18: TRUE
A19: 50mm_back_loaded | B19: 50 | C19: back_loaded | D19: 1.875 | E19: 30 | F19: 98 | G19: 10 | H19: 0.62 | I19: 50 | J19: 177.10337 | K19: 10 | L19: 187.10337 | M19: 0 | N19: 0 | O19: 1.834375 | P19: 0.085673949 | Q19: 59.984375 | R19: h0.750_o100 | S19: 0.75 | T19: 150 | U19: 100 | V19: 0.021940211 | W19: 74.391036 | X19: 76.171875 | Y19: 137.76136 | Z19: 0.68880682 | AA19: 0 | AC19: 187.01072 | AD19: 187.01072 | AE19: 0.092648516 | AF19: 7.8059894 | AG19: -5.7200612e-10 | AH19: 3.0571663e-12 | AI19: TRUE | AJ19: TRUE | AK19: TRUE | AL19: 0.40630308 | AM19: TRUE | AN19: lag_min | AO19: 10 | AP19: TRUE
A20: 50mm_uniform | B20: 50 | C20: uniform | D20: 1.875 | E20: 30 | F20: 98 | G20: 15 | H20: 0.62 | I20: 50 | J20: 177.10337 | K20: 10 | L20: 187.10337 | M20: 0 | N20: 0 | O20: 2.2510417 | P20: 0.056691839 | Q20: 59.984375 | R20: h0.750_o100 | S20: 0.75 | T20: 150 | U20: 100 | V20: 0.020748136 | W20: 63.401899 | X20: 80.296875 | Y20: 124.26987 | Z20: 0.62134936 | AA20: 0 | AC20: 187.01109 | AD20: 187.01109 | AE20: 0.092284736 | AF20: 7.7504576 | AG20: -5.9347971e-10 | AH20: 3.1719349e-12 | AI20: TRUE | AJ20: TRUE | AK20: TRUE | AL20: 0.38881763 | AM20: TRUE | AN20: lag_min | AO20: 15 | AP20: FALSE
A21: 50mm_front_loaded | B21: 50 | C21: front_loaded | D21: 1.875 | E21: 30 | F21: 98 | G21: 15 | H21: 0.62 | I21: 50 | J21: 177.10337 | K21: 10 | L21: 187.10337 | M21: 0 | N21: 0 | O21: 2.2510417 | P21: 0.066188978 | Q21: 34.078125 | R21: h0.750_o100 | S21: 0.75 | T21: 150 | U21: 100 | V21: 0.020701249 | W21: 68.724024 | X21: 71.109375 | Y21: 123.75465 | Z21: 0.61877326 | AA21: 0 | AC21: 187.012 | AD21: 187.012 | AE21: 0.091371402 | AF21: 7.6095768 | AG21: -6.0162281e-10 | AH21: 3.2154568e-12 | AI21: TRUE | AJ21: TRUE | AK21: TRUE | AL21: 0.44235512 | AM21: TRUE | AN21: lag_min | AO21: 15 | AP21: FALSE
A22: 50mm_back_loaded | B22: 50 | C22: back_loaded | D22: 1.875 | E22: 30 | F22: 98 | G22: 15 | H22: 0.62 | I22: 50 | J22: 177.10337 | K22: 10 | L22: 187.10337 | M22: 0 | N22: 0 | O22: 2.2510417 | P22: 0.075895893 | Q22: 65.890625 | R22: h0.750_o100 | S22: 0.75 | T22: 150 | U22: 100 | V22: 0.021343669 | W22: 71.877702 | X22: 84.046875 | Y22: 130.9155 | Z22: 0.65457752 | AA22: 0 | AC22: 187.01009 | AD22: 187.01009 | AE22: 0.093283891 | AF22: 7.9022003 | AG22: -5.7422579e-10 | AH22: 3.0690296e-12 | AI22: TRUE | AJ22: TRUE | AK22: TRUE | AL22: 0.39269571 | AM22: TRUE | AN22: lag_min | AO22: 15 | AP22: FALSE
A23: 50mm_uniform | B23: 50 | C23: uniform | D23: 1.875 | E23: 30 | F23: 98 | G23: 10 | H23: 0.5 | I23: 50 | J23: 177.10337 | K23: 10 | L23: 187.10337 | M23: 0 | N23: 0 | O23: 1.834375 | P23: 0.05747879 | Q23: 59.984375 | R23: h0.750_o100 | S23: 0.75 | T23: 150 | U23: 100 | V23: 0.017726506 | W23: 69.159917 | X23: 74.484375 | Y23: 138.23482 | Z23: 0.69117412 | AA23: 0 | AC23: 186.9601 | AD23: 186.9601 | AE23: 0.14326677 | AF23: 9.5681774 | AG23: -3.3318553e-10 | AH23: 1.7807564e-12 | AI23: TRUE | AJ23: TRUE | AK23: TRUE | AL23: 0.37670079 | AM23: TRUE | AN23: discharge_coefficient | AO23: 0.5 | AP23: FALSE
A24: 50mm_front_loaded | B24: 50 | C24: front_loaded | D24: 1.875 | E24: 30 | F24: 98 | G24: 10 | H24: 0.5 | I24: 50 | J24: 177.10337 | K24: 10 | L24: 187.10337 | M24: 0 | N24: 0 | O24: 1.834375 | P24: 0.073191362 | Q24: 26.234375 | R24: h0.750_o100 | S24: 0.75 | T24: 150 | U24: 100 | V24: 0.017601633 | W24: 75.951216 | X24: 66.765625 | Y24: 136.43634 | Z24: 0.6821817 | AA24: 0 | AC24: 186.96149 | AD24: 186.96149 | AE24: 0.14187698 | AF24: 9.4307717 | AG24: -3.2353811e-10 | AH24: 1.7291945e-12 | AI24: TRUE | AJ24: TRUE | AK24: TRUE | AL24: 0.39840221 | AM24: TRUE | AN24: discharge_coefficient | AO24: 0.5 | AP24: FALSE
A25: 50mm_back_loaded | B25: 50 | C25: back_loaded | D25: 1.875 | E25: 30 | F25: 98 | G25: 10 | H25: 0.5 | I25: 50 | J25: 177.10337 | K25: 10 | L25: 187.10337 | M25: 0 | N25: 0 | O25: 1.834375 | P25: 0.085673949 | Q25: 59.984375 | R25: h0.750_o100 | S25: 0.75 | T25: 150 | U25: 100 | V25: 0.01819989 | W25: 78.756798 | X25: 77.296875 | Y25: 145.16839 | Z25: 0.72584196 | AA25: 0 | AC25: 186.95851 | AD25: 186.95851 | AE25: 0.14485708 | AF25: 9.7229765 | AG25: -3.1855907e-10 | AH25: 1.7025833e-12 | AI25: TRUE | AJ25: TRUE | AK25: TRUE | AL25: 0.37985438 | AM25: TRUE | AN25: discharge_coefficient | AO25: 0.5 | AP25: FALSE
... A31: 50mm_back_loaded | B31: 50 | C31: back_loaded | D31: 1.875 | E31: 30 | F31: 98 | G31: 10 | H31: 0.75 | I31: 50 | J31: 177.10337 | K31: 10 | L31: 187.10337 | M31: 0 | N31: 0 | O31: 1.834375 | P31: 0.085673949 | Q31: 59.984375 | R31: h0.750_o100 | S31: 0.75 | T31: 150 | U31: 100 | V31: 0.025758769 | W31: 69.933955 | X31: 75.203125 | Y31: 130.35308 | Z31: 0.6517654 | AA31: 0 | AC31: 187.0408 | AD31: 187.0408 | AE31: 0.062567404 | AF31: 6.423208 | AG31: -9.1948475e-10 | AH31: 4.9143142e-12 | AI31: TRUE | AJ31: TRUE | AK31: TRUE | AL31: 0.36907067 | AM31: TRUE | AN31: discharge_coefficient | AO31: 0.75 | AP31: FALSE

Sheet Convergence
A1: Time-step verification
A2: Relative changes compare coarse and fine outputs. Overflow onset is the start of the first overflowing interval; drawdown uses the final threshold crossing.
A4: event_id | B4: design_id | C4: coarse_dt_s | D4: fine_dt_s | E4: peak_downstream_m3_s_relative_change | F4: maximum_storage_m3_relative_change | G4: baseline_peak_m3_s_relative_change | H4: overflow_change_m3 | I4: overflow_onset_change_s | J4: overflow_classification_stable | K4: drawdown_change_s | L4: acceptance_stable | M4: peak_storage_converged
A5: 25mm_uniform | B5: h0.150_o40 | C5: 30 | D5: 15 | E5: 0.00041582816 | F5: 0 | G5: 0.00041582816 | H5: 0.035182611 | I5: 15 | J5: TRUE | K5: 59.703658 | L5: TRUE | M5: TRUE
A6: 25mm_uniform | B6: h0.150_o60 | C6: 30 | D6: 15 | E6: 0.00041582816 | F6: 0 | G6: 0.00041582816 | H6: 0.062541533 | I6: 15 | J6: TRUE | K6: 59.152888 | L6: TRUE | M6: TRUE
A7: 25mm_uniform | B7: h0.150_o80 | C7: 30 | D7: 15 | E7: 0.00041582816 | F7: 0 | G7: 0.00041582816 | H7: 0.088287687 | I7: 15 | J7: TRUE | K7: 58.585753 | L7: TRUE | M7: TRUE
A8: 25mm_uniform | B8: h0.150_o100 | C8: 30 | D8: 15 | E8: 0.00041582816 | F8: 0 | G8: 0.00041582816 | H8: 0.11017135 | I8: 15 | J8: TRUE | K8: 58.318387 | L8: TRUE | M8: TRUE
A9: 25mm_uniform | B9: h0.300_o40 | C9: 30 | D9: 15 | E9: 0.00038893002 | F9: 0 | G9: 0.00041582816 | H9: 0.046763058 | I9: 15 | J9: TRUE | K9: 53.27718 | L9: TRUE | M9: TRUE
A10: 25mm_uniform | B10: h0.300_o60 | C10: 30 | D10: 15 | E10: 0.016300829 | F10: 0 | G10: 0.00041582816 | H10: 0.081559069 | I10: 15 | J10: TRUE | K10: 52.687421 | L10: TRUE | M10: FALSE
A11: 25mm_uniform | B11: h0.300_o80 | C11: 30 | D11: 15 | E11: 0.073501361 | F11: 0 | G11: 0.00041582816 | H11: 0.10877632 | I11: 15 | J11: TRUE | K11: 52.080799 | L11: TRUE | M11: FALSE
A12: 25mm_uniform | B12: h0.300_o100 | C12: 30 | D12: 15 | E12: 0.0013970878 | F12: 0.0022481221 | G12: 0.00041582816 | H12: 0 | J12: TRUE | K12: 42.652607 | L12: TRUE | M12: TRUE
A13: 25mm_uniform | B13: h0.450_o40 | C13: 30 | D13: 15 | E13: 0.00034294197 | F13: 0.00064927031 | G13: 0.00041582816 | H13: 0 | J13: TRUE | K13: 30.24852 | L13: TRUE | M13: TRUE
A14: 25mm_uniform | B14: h0.450_o60 | C14: 30 | D14: 15 | E14: 0.00066092892 | F14: 0.0012042111 | G14: 0.00041582816 | H14: 0 | J14: TRUE | K14: 33.579593 | L14: TRUE | M14: TRUE
A15: 25mm_uniform | B15: h0.450_o80 | C15: 30 | D15: 15 | E15: 0.0010233294 | F15: 0.0017703511 | G15: 0.00041582816 | H15: 0 | J15: TRUE | K15: 36.065326 | L15: TRUE | M15: TRUE
A16: 25mm_uniform | B16: h0.450_o100 | C16: 30 | D16: 15 | E16: 0.0013970878 | F16: 0.0022481221 | G16: 0.00041582816 | H16: 0 | J16: TRUE | K16: 38.095649 | L16: TRUE | M16: TRUE
A17: 25mm_uniform | B17: h0.600_o40 | C17: 30 | D17: 15 | E17: 0.00034294197 | F17: 0.00064927031 | G17: 0.00041582816 | H17: 0 | J17: TRUE | K17: 27.013534 | L17: TRUE | M17: TRUE
A18: 25mm_uniform | B18: h0.600_o60 | C18: 30 | D18: 15 | E18: 0.00066092892 | F18: 0.0012042111 | G18: 0.00041582816 | H18: 0 | J18: TRUE | K18: 30.342033 | L18: TRUE | M18: TRUE
A19: 25mm_uniform | B19: h0.600_o80 | C19: 30 | D19: 15 | E19: 0.0010233294 | F19: 0.0017703511 | G19: 0.00041582816 | H19: 0 | J19: TRUE | K19: 32.833263 | L19: TRUE | M19: TRUE
A20: 25mm_uniform | B20: h0.600_o100 | C20: 30 | D20: 15 | E20: 0.0013970878 | F20: 0.0022481221 | G20: 0.00041582816 | H20: 0 | J20: TRUE | K20: 34.865145 | L20: TRUE | M20: TRUE
A21: 25mm_uniform | B21: h0.750_o40 | C21: 30 | D21: 15 | E21: 0.00034294197 | F21: 0.00064927031 | G21: 0.00041582816 | H21: 0 | J21: TRUE | K21: 24.502837 | L21: TRUE | M21: TRUE
A22: 25mm_uniform | B22: h0.750_o60 | C22: 30 | D22: 15 | E22: 0.00066092892 | F22: 0.0012042111 | G22: 0.00041582816 | H22: 0 | J22: TRUE | K22: 27.834824 | L22: TRUE | M22: TRUE
A23: 25mm_uniform | B23: h0.750_o80 | C23: 30 | D23: 15 | E23: 0.0010233294 | F23: 0.0017703511 | G23: 0.00041582816 | H23: 0 | J23: TRUE | K23: 30.324023 | L23: TRUE | M23: TRUE
... A28: 25mm_uniform | B28: h0.900_o100 | C28: 30 | D28: 15 | E28: 0.0013970878 | F28: 0.0022481221 | G28: 0.00041582816 | H28: 0 | J28: TRUE | K28: 30.311352 | L28: TRUE | M28: TRUE
A29: 25mm_front_loaded | B29: h0.150_o40 | C29: 30 | D29: 15 | E29: 0.0021004911 | F29: 0 | G29: 0.0021867696 | H29: 0.031465331 | I29: 15 | J29: TRUE | K29: 56.723765 | L29: TRUE | M29: TRUE
A30: 25mm_front_loaded | B30: h0.150_o60 | C30: 30 | D30: 15 | E30: 0.0020812509 | F30: 0 | G30: 0.0021867696 | H30: 0.054332864 | I30: 15 | J30: TRUE | K30: 56.031036 | L30: TRUE | M30: TRUE
A31: 25mm_front_loaded | B31: h0.150_o80 | C31: 30 | D31: 15 | E31: 0.0034047078 | F31: 0 | G31: 0.0021867696 | H31: 0.076501271 | I31: 0 | J31: TRUE | K31: 55.810446 | L31: TRUE | M31: TRUE
A32: 25mm_front_loaded | B32: h0.150_o100 | C32: 30 | D32: 15 | E32: 0.0021250179 | F32: 0 | G32: 0.0021867696 | H32: 0.095227612 | I32: 15 | J32: TRUE | K32: 55.718758 | L32: TRUE | M32: TRUE
A33: 25mm_front_loaded | B33: h0.300_o40 | C33: 30 | D33: 15 | E33: 0.003429524 | F33: 0 | G33: 0.0021867696 | H33: 0.040343881 | I33: 15 | J33: TRUE | K33: 50.251426 | L33: TRUE | M33: TRUE
A34: 25mm_front_loaded | B34: h0.300_o60 | C34: 30 | D34: 15 | E34: 0.02081258 | F34: 0 | G34: 0.0021867696 | H34: 0.067968453 | I34: 15 | J34: TRUE | K34: 49.82355 | L34: TRUE | M34: FALSE
A35: 25mm_front_loaded | B35: h0.300_o80 | C35: 30 | D35: 15 | E35: 0.00081071986 | F35: 0.0013975832 | G35: 0.0021867696 | H35: 0 | J35: TRUE | K35: 40.42885 | L35: TRUE | M35: TRUE
A36: 25mm_front_loaded | B36: h0.300_o100 | C36: 30 | D36: 15 | E36: 0.0011702259 | F36: 0.0018682532 | G36: 0.0021867696 | H36: 0 | J36: TRUE | K36: 42.510062 | L36: TRUE | M36: TRUE
A37: 25mm_front_loaded | B37: h0.450_o40 | C37: 30 | D37: 15 | E37: 0.00029320046 | F37: 0.00055497111 | G37: 0.0021867696 | H37: 0 | J37: TRUE | K37: 30.024903 | L37: TRUE | M37: TRUE
A38: 25mm_front_loaded | B38: h0.450_o60 | C38: 30 | D38: 15 | E38: 0.00054723338 | F38: 0.00099593284 | G38: 0.0021867696 | H38: 0 | J38: TRUE | K38: 33.361269 | L38: TRUE | M38: TRUE
A39: 25mm_front_loaded | B39: h0.450_o80 | C39: 30 | D39: 15 | E39: 0.00081071986 | F39: 0.0013975832 | G39: 0.0021867696 | H39: 0 | J39: TRUE | K39: 35.872932 | L39: TRUE | M39: TRUE
A40: 25mm_front_loaded | B40: h0.450_o100 | C40: 30 | D40: 15 | E40: 0.0011702259 | F40: 0.0018682532 | G40: 0.0021867696 | H40: 0 | J40: TRUE | K40: 37.94505 | L40: TRUE | M40: TRUE
A41: 25mm_front_loaded | B41: h0.600_o40 | C41: 30 | D41: 15 | E41: 0.00029320046 | F41: 0.00055497111 | G41: 0.0021867696 | H41: 0 | J41: TRUE | K41: 26.789062 | L41: TRUE | M41: TRUE
A42: 25mm_front_loaded | B42: h0.600_o60 | C42: 30 | D42: 15 | E42: 0.00054723338 | F42: 0.00099593284 | G42: 0.0021867696 | H42: 0 | J42: TRUE | K42: 30.13067 | L42: TRUE | M42: TRUE
A43: 25mm_front_loaded | B43: h0.600_o80 | C43: 30 | D43: 15 | E43: 0.00081071986 | F43: 0.0013975832 | G43: 0.0021867696 | H43: 0 | J43: TRUE | K43: 32.639985 | L43: TRUE | M43: TRUE
A44: 25mm_front_loaded | B44: h0.600_o100 | C44: 30 | D44: 15 | E44: 0.0011702259 | F44: 0.0018682532 | G44: 0.0021867696 | H44: 0 | J44: TRUE | K44: 34.719438 | L44: TRUE | M44: TRUE
A45: 25mm_front_loaded | B45: h0.750_o40 | C45: 30 | D45: 15 | E45: 0.00029320046 | F45: 0.00055497111 | G45: 0.0021867696 | H45: 0 | J45: TRUE | K45: 24.280239 | L45: TRUE | M45: TRUE
...

Sheet Sources
A1: Source register
A2: All numerical source data are bundled with the project. URLs document provenance and are not needed for recomputation.
A4: id | B4: title | C4: url | D4: accessed | E4: use
A5: cn | B5: USACE HEC-HMS Technical Reference: SCS Curve Number Loss Model | C5: https://www.hec.usace.army.mil/confluence/hmsdocs/hmstrm/canopy-surface-infiltration-and-runoff-volume/infiltration/scs-curve-number-loss-model | D5: 2026-09-08 | E5: Cumulative event runoff equation, incremental differencing, and event-only limitation. CN 98 is a project assumption.
A6: uh | B6: USACE HEC-HMS Technical Reference: SCS Unit Hydrograph Model | C6: https://www.hec.usace.army.mil/confluence/hmsdocs/hmstrm/transform/scs-unit-hydrograph-model | D6: 2026-09-08 | E6: Tp = lag + excess-rainfall interval / 2; dimensionless hydrograph interpretation.
A7: ordinates | B7: TxDOT Hydraulic Design Manual: NRCS Dimensionless Unit Hydrograph, Table 4-29 | C7: https://www.txdot.gov/manuals/des/hyd/chapter-4--hydrology/section-13--hydrograph-method/nrcs-dimensionless-unit-hydrograph.html | D7: 2026-09-08 | E7: All 33 time and discharge ordinate pairs in scs_dimensionless_uh.csv, including terminal (5, 0). Table 4-29, not the rounded worked example in Table 4-30.
A8: routing | B8: USACE HEC-HMS Technical Reference: Reservoir Modeling Concepts and Equations | C8: https://www.hec.usace.army.mil/confluence/hmsdocs/hmstrm/reservoir-modeling/reservoir-modeling-concepts-and-equations | D8: 2026-09-08 | E8: Level-pool continuity and storage/outflow relationships. This project uses backward Euler, not the manual's trapezoidal Modified Puls implementation.
A9: outlet | B9: USACE HEC-HMS User's Manual: Outflow Structures Routing | C9: https://www.hec.usace.army.mil/confluence/hmsdocs/hmsum/latest/reservoir-elements/outflow-structures-routing | D9: 2026-09-08 | E9: Outlet submergence limitations. The vertically integrated floor opening with constant Cd is the project's idealized rating, not a copied or calibrated HEC-HMS structure.
A10: selection | B10: TxDOT Hydraulic Design Manual: Selection of the Appropriate Method for Calculating Runoff | C10: https://www.txdot.gov/manuals/des/hyd/chapter-4--hydrology/section-7--selection-of-the-appropriate-method-for.html | D10: 2026-09-08 | E10: Need for an event hydrograph for storage calculations rather than a peak-only runoff estimate.
